Workbook
Name DIV: #REF!
Name suppliers.name: #REF!
Name NP: #REF!
Name NP: #REF!
Name VM: #REF!
Name DIV: #REF!
Name DEPT: #REF!
Name Period: #REF!
Name NP: #REF!
Name VM: #REF!
Name PD: #REF!
Name n.p: #REF!
Name RNYR: #REF!
Name n.p: #REF!
Name suppliers.name: #REF!
Name a: #REF!
Name CO: #REF!
Name YR: #REF!
Name YR: #REF!
Name RNYR: #REF!
Name PD: #REF!
Name Period: #REF!
Name DIV: #REF!
Name a: #REF!
Name DEPT: #REF!
Name Period: #REF!
Name CO: #REF!
Name suppliers.name: #REF!
Name a: #REF!
Name CO: #REF!
Name RNYR: #REF!
Name VM: #REF!
Name n.p: #REF!
Name PD: #REF!
Name YR: #REF!
Name DEPT: #REF!

Sheet A. Process Flow Sample Template
B2: 1. ACTIVITY: INBOUND
B3: STEP # | C3: ELEMENTS | D3: AVE (sec) | E3: MAX(sec) | F3: AVE (min) | G3: MAX(min) | H3: % | I3: BOTTLENECK | J3: RECOMMENDATION
B4: 1 | C4: =A. Process Flow Sample Template!C4 -> #ERROR! | D4: =#REF! -> #REF! | E4: =#REF! -> #REF! | F4: =D4/60 -> #REF! | G4: =E4/60 -> #REF! | H4: =#REF! -> #REF! | I4: =#REF! -> #REF! | J4: =#REF! -> #REF!
B5: TOTAL | D5: =SUM(D4) -> #REF! | E5: =SUM(E4) -> #REF! | F5: =D5/60 -> #REF! | G5: =E5/60 -> #REF! | H5: =sum(H4) -> #REF!
F6: =F5/60 -> #REF!
B7: ACTIVITY: PUTAWAY (HIGH-JUMP)
B8: STEP # | C8: ELEMENTS | D8: AVE (sec) | E8: MAX(sec) | H8: % | I8: BOTTLENECK | J8: RECOMMENDATION
B9: 1 | C9: ='2. PUTAWAY'!C56 -> #REF! | D9: =#REF! -> #REF! | E9: =#REF! -> #REF! | H9: =#REF! -> #REF! | I9: =#REF! -> #REF! | J9: =#REF! -> #REF!
B10: 2 | C10: ='2. PUTAWAY'!C57 -> #REF! | H10: =#REF! -> #REF!
B11: TOTAL | D11: =SUM(D9) -> #REF! | E11: =SUM(E9) -> #REF! | H11: 1
B13: 2. ACTIVITY: PUTAWAY (HATIO)
B14: STEP # | C14: ELEMENTS | D14: AVE (sec) | E14: MAX(sec) | F14: AVE (min) | G14: MAX(min) | H14: % | I14: BOTTLENECK | J14: RECOMMENDATION
B15: 1 | C15: ='2. PUTAWAY'!C9 -> #REF! | D15: ='2. PUTAWAY'!P9 -> #REF! | E15: ='2. PUTAWAY'!Q9 -> #REF! | F15: =D15/60 -> #REF! | G15: =E15/60 -> #REF! | H15: ='2. PUTAWAY'!R9 -> #REF! | I15: ='2. PUTAWAY'!S9 -> #REF! | J15: ='2. PUTAWAY'!T9 -> #REF!
B16: 2 | C16: ='2. PUTAWAY'!C10 -> #REF! | D16: ='2. PUTAWAY'!P10 -> #REF! | E16: ='2. PUTAWAY'!Q10 -> #REF! | F16: =D16/60 -> #REF! | G16: =E16/60 -> #REF! | H16: ='2. PUTAWAY'!R10 -> #REF! | I16: ='2. PUTAWAY'!S10 -> #REF! | J16: ='2. PUTAWAY'!T10 -> #REF!
B17: TOTAL | D17: =sum(D15:D16) -> #REF! | E17: =sum(E15:E16) -> #REF! | F17: =D17/60 -> #REF! | G17: =E17/60 -> #REF! | H17: =sum(H15:H16) -> #REF!
F18: =F17/60 -> #REF!
B19: 3. ACTIVITY: RELEASE OF ORDERS (HIGH-JUMP)
B20: STEP # | C20: ELEMENTS | D20: AVE (sec) | E20: MAX(sec) | F20: AVE (min) | G20: MAX(min) | H20: % | I20: BOTTLENECK | J20: RECOMMENDATION
B21: 1 | C21: ='3. RELEASING OF WAVE ORDERS'!C9 -> #REF! | D21: ='3. RELEASING OF WAVE ORDERS'!P9 -> #REF! | E21: ='3. RELEASING OF WAVE ORDERS'!Q9 -> #REF! | F21: =D21/60 -> #REF! | G21: =E21/60 -> #REF! | H21: ='3. RELEASING OF WAVE ORDERS'!R9 -> #REF! | I21: ='3. RELEASING OF WAVE ORDERS'!S9 -> #REF! | J21: ='3. RELEASING OF WAVE ORDERS'!T9 -> #REF!
B22: 2 | C22: ='3. RELEASING OF WAVE ORDERS'!C10 -> #REF! | D22: ='3. RELEASING OF WAVE ORDERS'!P10 -> #REF! | E22: ='3. RELEASING OF WAVE ORDERS'!Q10 -> #REF! | F22: =D22/60 -> #REF! | G22: =E22/60 -> #REF! | H22: ='3. RELEASING OF WAVE ORDERS'!R10 -> #REF! | I22: ='3. RELEASING OF WAVE ORDERS'!S10 -> #REF! | J22: ='3. RELEASING OF WAVE ORDERS'!T10 -> #REF!
B23: TOTAL | D23: =sum(D21:D22) -> #REF! | E23: =sum(E21:E22) -> #REF! | F23: =D23/60 -> #REF! | G23: =E23/60 -> #REF! | H23: =sum(H21:H22) -> #REF!
B25: 3.1 ACTIVITY: RELEASE OF ORDERS (HATIO)
B26: STEP # | C26: ELEMENTS | D26: AVE (sec) | E26: MAX(sec) | F26: AVE (min) | G26: MAX(min) | H26: % | I26: BOTTLENECK | J26: RECOMMENDATION
B27: 1 | C27: ='3. RELEASING OF WAVE ORDERS'!C36 -> #REF! | D27: ='3. RELEASING OF WAVE ORDERS'!P36 -> #REF! | E27: ='3. RELEASING OF WAVE ORDERS'!Q36 -> #REF! | F27: =D27/60 -> #REF! | G27: =E27/60 -> #REF! | H27: ='3. RELEASING OF WAVE ORDERS'!R36 -> #REF! | I27: ='3. RELEASING OF WAVE ORDERS'!S36 -> #REF! | J27: ='3. RELEASING OF WAVE ORDERS'!T36 -> #REF!
B28: TOTAL | D28: =SUM(D27) -> #REF! | E28: =SUM(E27) -> #REF! | F28: =D28/60 -> #REF! | G28: =E28/60 -> #REF! | H28: =sum(H27) -> #REF!
B30: 4. ACTIVITY: BATCH BY ORDER (HIGH-JUMP)
B31: STEP # | C31: ELEMENTS | D31: AVE (sec) | E31: MAX(sec) | F31: AVE (min) | G31: MAX(min) | H31: % | I31: BOTTLENECK | J31: RECOMMENDATION
B32: 1 | C32: ='4. BATCH BY ORDER'!C9 -> #REF! | D32: ='4. BATCH BY ORDER'!P9 -> #REF! | E32: ='4. BATCH BY ORDER'!Q9 -> #REF! | F32: =D32/60 -> #REF! | G32: =E32/60 -> #REF! | H32: ='4. BATCH BY ORDER'!R9 -> #REF! | I32: ='4. BATCH BY ORDER'!S9 -> #REF! | J32: ='4. BATCH BY ORDER'!T9 -> #REF!
B33: 2 | C33: ='4. BATCH BY ORDER'!C10 -> #REF! | D33: ='4. BATCH BY ORDER'!P10 -> #REF! | E33: ='4. BATCH BY ORDER'!Q10 -> #REF! | F33: =D33/60 -> #REF! | G33: =E33/60 -> #REF! | H33: ='4. BATCH BY ORDER'!R10 -> #REF!
B34: 3 | C34: ='4. BATCH BY ORDER'!C11 -> #REF! | D34: ='4. BATCH BY ORDER'!P11 -> #REF! | E34: ='4. BATCH BY ORDER'!Q11 -> #REF! | F34: =D34/60 -> #REF! | G34: =E34/60 -> #REF! | H34: ='4. BATCH BY ORDER'!R11 -> #REF!
B35: 4 | C35: ='4. BATCH BY ORDER'!C12 -> #REF! | D35: ='4. BATCH BY ORDER'!P12 -> #REF! | E35: ='4. BATCH BY ORDER'!Q12 -> #REF! | F35: =D35/60 -> #REF! | G35: =E35/60 -> #REF! | H35: ='4. BATCH BY ORDER'!R12 -> #REF!
B36: TOTAL | D36: =SUM(D32:D35) -> #REF! | E36: =SUM(E32:E35) -> #REF! | F36: =D36/60 -> #REF! | G36: =E36/60 -> #REF! | H36: =sum(H32:H35) -> #REF! | I36: ='4. BATCH BY ORDER'!S3 -> #REF!
B38: 5. ACTIVITY: SUMMARY OF ORDERS (HIGH-JUMP)
B39: STEP # | C39: ELEMENTS | D39: AVE (sec) | E39: MAX(sec) | F39: AVE (min) | G39: MAX(min) | H39: % | I39: BOTTLENECK | J39: RECOMMENDATION
B40: 1 | C40: ='5. SOP/MOTHER PICKLIST PRINTING'!C9 -> #REF! | D40: ='5. SOP/MOTHER PICKLIST PRINTING'!P9 -> #REF! | E40: ='5. SOP/MOTHER PICKLIST PRINTING'!Q9 -> #REF! | F40: =D40/60 -> #REF! | G40: =E40/60 -> #REF! | H40: ='5. SOP/MOTHER PICKLIST PRINTING'!R9 -> #REF! | I40: ='5. SOP/MOTHER PICKLIST PRINTING'!S9 -> #REF! | J40: ='5. SOP/MOTHER PICKLIST PRINTING'!T9 -> #REF!
B41: TOTAL | D41: =SUM(D40) -> #REF! | E41: =SUM(E40) -> #REF! | F41: =D41/60 -> #REF! | G41: =E41/60 -> #REF! | H41: =sum(H40) -> #REF!
B43: 6. ACTIVITY: WAYBILL PRINTING (HIGH-JUMP)
B44: STEP # | C44: ELEMENTS | D44: AVE (sec) | E44: MAX(sec) | F44: AVE (min) | G44: MAX(min) | H44: % | I44: BOTTLENECK | J44: RECOMMENDATION
B45: 1 | C45: ='6. WAYBILL PRINTING'!C9 -> #REF! | D45: ='6. WAYBILL PRINTING'!P9 -> #REF! | E45: ='6. WAYBILL PRINTING'!Q9 -> #REF! | F45: =D45/60 -> #REF! | G45: =E45/60 -> #REF! | H45: ='6. WAYBILL PRINTING'!R9 -> #REF! | I45: ='6. WAYBILL PRINTING'!S9 -> #REF! | J45: ='6. WAYBILL PRINTING'!T9 -> #REF!
B46: TOTAL | D46: =SUM(D45) -> #REF! | E46: =SUM(E45) -> #REF! | F46: =D46/60 -> #REF! | G46: =E46/60 -> #REF! | H46: =sum(H45) -> #REF!
...

Sheet B. Assmptns,Vlme,Prdctvty
C3: I. ASSUMPTIONS
C5: Operating Hours | E5: UOM (unit of measurement)
C6: No. of Weeks per Year (2021) | D6: 52 | E6: weeks
C7: No. of Weeks per Month | D7: =D6/12 -> 4.3333333 | E7: weeks
C8: No. of Days per Month | D8: =D7*6 -> 26 | E8: days
C9: Working Hours per Day | D9: 8 | E9: hours
C11: Reference:
C12: https://www.timeanddate.com/date/workdays.html?d1=1&m1=1&y1=2021&d2=31&m2=12&y2=2021&ti=on&
C15: II. VOLUME
D16: Existing Volume | E16: 40% Volume Increase
C17: Ave No. of Stores per Pick-up | D17: 35 | E17: =D17*1.4 -> 49
C18: Ave No. of Trucks (Ave: 3 drops) per day | D18: =D17/3 -> 11.666667 | E18: =E17/3 -> 16.333333
C19: Number of Pallets per Pick-up | D19: 17 | E19: =E21/1.3 -> 56
C20: Ave No. of 10W per Pick-up | D20: 1 | E20: =D20*1.4 -> 1.4
C21: Ave No. of CBM per day | D21: 52 | E21: =D21*1.4 -> 72.8
C22: Ave Weight per Pick-up | D22: 18790.163 | E22: =D22*1.4 -> 26306.228
C23: Ave Invoice Value per Pick-up | D23: 1013938.8 | E23: =D23*1.4 -> 1419514.3
C24: Ave. No of Pallets per day | D24: =D21/(1.2*1.1*1) -> 39.393939 | E24: =D24*1.4 -> 55.151515
C26: II. PRODUCTIVITY SUMMARY
B27: NO | C27: PROCESS | D27: UOM | E27: Standard Time per Unit (secs) | F27: Standard Time per Unit (minutes) | G27: Productivity Unit per Man-hour | H27: Productivity Unit per Man-day @ 8 hrs
B28: 1 | D28: Per Box | E28: =#REF! -> #REF! | F28: =E28/60 -> #REF! | G28: =#REF! -> #REF! | H28: =G28*8 -> #REF!
D29: Per Item | E29: =#REF! -> #REF! | F29: =E29/60 -> #REF! | G29: =#REF! -> #REF! | H29: =G29*8 -> #REF!
D30: Per Pallet | E30: =#REF! -> #REF! | F30: =E30/60 -> #REF! | G30: =#REF! -> #REF! | H30: =G30*8 -> #REF!
D31: Per Sales Invoice | E31: =#REF! -> #REF! | F31: =E31/60 -> #REF! | G31: =#REF! -> #REF! | H31: =G31*8 -> #REF!
B33: 2 | D33: Per Item | E33: ='2. PUTAWAY'!N36 -> #REF! | F33: =E33/60 -> #REF! | G33: ='2. PUTAWAY'!N37 -> #REF! | H33: =G33*8 -> #REF!
D34: Per Sales Invoice | E34: ='2. PUTAWAY'!N29 -> #REF! | F34: =E34/60 -> #REF! | G34: ='2. PUTAWAY'!N30 -> #REF! | H34: =G34*8 -> #REF!
D35: Per Box | E35: ='2. PUTAWAY'!N43 -> #REF! | F35: =E35/60 -> #REF! | G35: ='2. PUTAWAY'!N44 -> #REF! | H35: =G35*8 -> #REF!
D36: Per Item | E36: ='2. PUTAWAY'!N36 -> #REF! | F36: =E36/60 -> #REF! | G36: ='2. PUTAWAY'!N75 -> #REF! | H36: =G36*8 -> #REF!
D37: Per Box | E37: ='2. PUTAWAY'!N43 -> #REF! | F37: =E37/60 -> #REF! | G37: ='2. PUTAWAY'!N82 -> #REF! | H37: =G37*8 -> #REF!
B39: 3 | D39: Per Order | E39: ='3. RELEASING OF WAVE ORDERS'!N25 -> #REF! | F39: =E39/60 -> #REF! | G39: ='3. RELEASING OF WAVE ORDERS'!N26 -> #REF! | H39: =G39*8 -> #REF!
D41: Per Batch | E41: ='3. RELEASING OF WAVE ORDERS'!N53 -> #REF! | F41: =E41/60 -> #REF! | G41: ='3. RELEASING OF WAVE ORDERS'!N54 -> #REF! | H41: =G41*8 -> #REF!
D42: Per Order | E42: ='3. RELEASING OF WAVE ORDERS'!N59 -> #REF! | F42: =E42/60 -> #REF! | G42: ='3. RELEASING OF WAVE ORDERS'!N60 -> #REF! | H42: =G42*8 -> #REF!
B44: 4 | D44: Per Order | E44: ='4. BATCH BY ORDER'!N29 -> #REF! | F44: =E44/60 -> #REF! | G44: ='4. BATCH BY ORDER'!N30 -> #REF! | H44: =G44*8 -> #REF!
D45: Per Wave | E45: ='4. BATCH BY ORDER'!N35 -> #REF! | F45: =E45/60 -> #REF! | G45: ='4. BATCH BY ORDER'!N36 -> #REF! | H45: =G45*8 -> #REF!
B47: 5 | D47: Per Wave | E47: ='5. SOP/MOTHER PICKLIST PRINTING'!N34 -> #REF! | F47: =E47/60 -> #REF! | G47: ='5. SOP/MOTHER PICKLIST PRINTING'!N35 -> #REF! | H47: =G47*8 -> #REF!
D48: Per SOP/Mother Picklist | E48: ='5. SOP/MOTHER PICKLIST PRINTING'!N28 -> #REF! | F48: =E48/60 -> #REF! | G48: ='5. SOP/MOTHER PICKLIST PRINTING'!N29 -> #REF! | H48: =G48*8 -> #REF!
D49: Per Order | E49: ='5. SOP/MOTHER PICKLIST PRINTING'!N40 -> #REF! | F49: =E49/60 -> #REF! | G49: ='5. SOP/MOTHER PICKLIST PRINTING'!N41 -> #REF! | H49: =G49*8 -> #REF!
B51: 6 | D51: Per Waybill/Order | E51: ='6. WAYBILL PRINTING'!N27 -> #REF! | F51: =E51/60 -> #REF! | G51: ='6. WAYBILL PRINTING'!N28 -> #REF! | H51: =G51*8 -> #REF!
D52: Per Wave | E52: ='6. WAYBILL PRINTING'!N34 -> #REF! | F52: =E52/60 -> #REF! | G52: ='6. WAYBILL PRINTING'!N35 -> #REF! | H52: =G52*8 -> #REF!
B54: 7 | D54: Per Wave | E54: ='7. BULK PICKING'!N47 -> #REF! | F54: =E54/60 -> #REF! | G54: ='7. BULK PICKING'!N48 -> #REF! | H54: =G54*8 -> #REF!
...

Sheet PROD SUMMARY 2
A1: PRODUCTIVITY SUMMARY
A2: PROCESS | B2: UOM | C2: Standard Time per Unit (secs) | D2: Standard Time per Unit (minutes) | E2: Productivity Unit per Man-hour | F2: Productivity Unit per Man-day @ 8 hrs
A3: PICKLIST,STORE LABEL ID & WAYBILL PREPARATION | B3: per Waybill | C3: ='PICKING-MONDELEZ'!#REF! -> #ERROR! | D3: =C3/60 -> #ERROR! | E3: ='PICKING-MONDELEZ'!#REF! -> #ERROR! | F3: =E3*8 -> #ERROR!
A4: Unloading | B4: Per Pallet | C4: =#REF! -> #REF! | D4: =C4/60 -> #REF! | E4: =#REF! -> #REF! | F4: =E4*8 -> #REF!
A5: Sorting | B5: Per Store/Waybill | C5: =#REF! -> #REF! | D5: =C5/60 -> #REF! | E5: =#REF! -> #REF! | F5: =E5*8 -> #REF!
B6: Per Pallet | C6: =#REF! -> #REF! | D6: =C6/60 -> #REF! | E6: =#REF! -> #REF! | F6: =E6*8 -> #REF!
B7: Per Box | C7: =#REF! -> #REF! | D7: =C7/60 -> #REF! | E7: =#REF! -> #REF! | F7: =E7*8 -> #REF!
B8: Per Amount | C8: =#REF! -> #REF! | D8: =C8/60 -> #REF! | E8: =#REF! -> #REF! | F8: =E8*8 -> #REF!
A9: Dispatching | B9: Per Box | C9: =#REF! -> #REF! | D9: =C9/60 -> #REF! | E9: =#REF! -> #REF! | F9: =E9*8 -> #REF!
B10: Per Truck | C10: =#REF! -> #REF! | D10: =C10/60 -> #REF! | E10: =#REF! -> #REF! | F10: =E10*8 -> #REF!
B11: Per Waybill/Store | C11: =#REF! -> #REF! | D11: =C11/60 -> #REF! | E11: =#REF! -> #REF! | F11: =E11*8 -> #REF!

Sheet SUMMARY
B4: Work Environment | C4: Allowances | D4: Minutes
B5: Temperature | C5: 0.01 | D5: 4.8
B6: Noise | C6: 0.02 | D6: 9.6
B7: Posture | C7: 0.02 | D7: 9.6
B8: Total | C8: =sum(C5:C7) -> 0.05 | D8: 24 | E8: Note: Additional 5% on Put-Away Process for the Machine Allowance
B10: Manpower Requirement (AVERAGE)
B11: ACTIVITY | C11: MAIN UOM | D11: Average Volume/Day | E11: Productivity Per Manhour | F11: Productivity Per Day | G11: Manpower Per Shift | H11: Required Manpower | I11: Manpower Per Shift
I12: 2
B13: Inbound Checking | C13: Pcs | D13: 176515 | E13: ='INBOUND CHECKING'!N39 -> 36713.07 | F13: =8*E13 -> 293704.56 | G13: 2 | H13: =roundup(D13/F13,0) -> 1 | I13: =H13*$I$12 -> 2
C14: Pallet | D14: 67 | E14: =E13/2920 -> 12.572969 | F14: =8*E14 -> 100.58375 | G14: 2 | H14: =roundup(D14/F14,0) -> 1 | I14: =H14*$I$12 -> 2
B15: Put-Away | C15: Pcs | D15: 203859 | E15: ='PUT-AWAY'!N40 -> 5904.7343 | F15: =8*E15 -> 47237.875 | G15: 1 | H15: =roundup(D15/F15,0) -> 5 | I15: =H15*$I$12 -> 10
C16: Pallet | D16: 103 | E16: ='PUT-AWAY'!N28 -> 30.272478 | F16: =8*E16 -> 242.17982 | G16: 2 | H16: =ROUNDUP(D16/F16,0) -> 1 | I16: =H16*$I$12 -> 2
B17: Picking (PMRL) | C17: Pallet | E17: =PICKING!N29 -> 9.5914649 | F17: =8*E17 -> 76.731719 | G17: 4 | H17: =roundup(D17/F17,0) -> 0 | I17: =H17 -> 0
C18: Picklist | D18: 23.63 | E18: =PICKING!N35 -> 7.0791809 | F18: =8*E18 -> 56.633447 | G18: 4 | H18: =roundup(D18/F18,0) -> 1 | I18: =H18 -> 1
C19: Pcs | D19: 103994 | E19: =PICKING!N41 -> 629.296 | F19: =8*E19 -> 5034.368 | G19: 4 | H19: =roundup(D19/F19,0) -> 21 | I19: =H19 -> 21
B20: Picking (SBU) | C20: Pallet | E20: =PICKING!N70 -> 1.4626849 | F20: =E20*8 -> 11.701479 | G20: 4 | H20: =roundup(D20/F20,0) -> 0 | I20: =H20 -> 0
C21: Store | D21: 55 | E21: =PICKING!N76 -> 3.4862732 | F21: =E21*8 -> 27.890186 | G21: 4 | H21: =roundup(D21/F21,0) -> 2 | I21: =H21 -> 2
C22: Pcs | D22: 103994 | E22: =PICKING!N82 -> 1041.4453 | F22: =E22*8 -> 8331.562 | G22: 4 | H22: =roundup(D22/F22,0) -> 13 | I22: =H22 -> 13
B23: Outbound Checking | C23: Pallet | D23: 122 | E23: ='OUTBOUND CHECKING'!N27 -> 11.631483 | F23: =8*E23 -> 93.051861 | G23: 2 | H23: =roundup(D23/F23,0) -> 2 | I23: =H23*$I$12 -> 4
C24: Pcs | D24: 103994 | E24: ='OUTBOUND CHECKING'!N39 -> 1349.7881 | F24: =8*E24 -> 10798.305 | G24: 2 | H24: =roundup(D24/F24,0) -> 10 | I24: =H24*$I$12 -> 20
B26: For Improvements: | C26: 5s
C27: Workers Ergonomics
C28: Handling
C29: Stacking of Items
C30: Additional MHE

Sheet JACKWRAP UTILIZATION
B2: Jack Wrap Utilization
B3: Roll Size | C3: 300 m
B4: Pallet Size | C4: 1.20 x 1 m
B5: Maximum Stack Height | C5: 1.25 m
B6: Wrap Level | C6: 7
B8: Assuming that Jack Wrap Streches 150%
B9: 300 m = 450 m
B11: Average Consumption per Pallet
B12: 38.5m
B14: Pallet per Roll
B15: 11 Pallets

Sheet INBOUND CHECKING
B2: TIME AND MOTION STUDY SHEET
B3: Process being observed: | E3: Observer(s): | H3: DAY/TIME of observation: | K3: Name and Designation
B4: INBOUND UNLOADING | E4: Hans David Wenceslao
B7: Step No. | C7: Elements | D7: OBSERVED TIMES (sec) | N7: Total Observed Time | P7: AVE | Q7: MAX | R7: WEIGHT PERCENTAGE | S7: Bottleneck | T7: Improvement
D8: T1 | E8: T2 | F8: T3 | G8: T4 | H8: T5 | I8: T6 | J8: T7 | K8: T8 | L8: T9 | M8: T10 | N8: (10 Trials)
B9: 1 | C9: Checking | D9: 275.73 | E9: 183.55 | F9: 220.1 | G9: 253.19 | H9: 176.19 | I9: 179.18 | J9: 174.91 | K9: 165.75 | L9: 263.31 | M9: 156.34 | N9: =SUM(D9:M9) -> 2048.25 | P9: =Iferror(AVERAGE(D9:M9),0) -> 204.825 | Q9: =MAX(D9:M9) -> 275.73 | R9: =Iferror(P9/$P$10,0) -> 1
C10: TOTAL Observed time (Sec) | D10: =sum(D9) -> 275.73 | E10: =sum(E9) -> 183.55 | F10: =sum(F9) -> 220.1 | G10: =sum(G9) -> 253.19 | H10: =sum(H9) -> 176.19 | I10: =sum(I9) -> 179.18 | J10: =sum(J9) -> 174.91 | K10: =sum(K9) -> 165.75 | ... M10: =sum(M9) -> 156.34 | N10: =SUM(D10:M10) -> 2048.25 | O10: TOTAL | P10: =SUM(P9) -> 204.825 | Q10: =SUM(Q9) -> 275.73 | R10: =SUM(R9) -> 1
C11: TOTAL Observed time (Min) | D11: =D10/60 -> 4.5955 | E11: =E10/60 -> 3.0591667 | F11: =F10/60 -> 3.6683333 | G11: =G10/60 -> 4.2198333 | H11: =H10/60 -> 2.9365 | I11: =I10/60 -> 2.9863333 | J11: =J10/60 -> 2.9151667 | K11: =K10/60 -> 2.7625 | ... N11: =N10/60 -> 34.1375
N12: minutes
C13: Number of Pallet | D13: 1 | E13: 1 | F13: 1 | G13: 1 | H13: 1 | I13: 1 | J13: 1 | K13: 1 | L13: 1 | M13: 1
C14: Number of Boxes/Pack
C15: Number of Items | D15: 5750 | E15: 2700 | F15: 3400 | G15: 8000 | H15: 1850 | I15: 1500 | J15: 1500 | K15: 1500 | L15: 1500 | M15: 1500 | N15: =SUM(D15:M15) -> 29200 | O15: =N15/10 -> 2920
C16: Number of Trucks | D16: 3 | E16: 1 | F16: 2 | G16: 3 | H16: 2 | I16: 2 | J16: 1 | K16: 1 | L16: 1 | M16: 1
C17: Account & Brand | D17: Contis | E17: Contis | F17: Contis | G17: Contis | H17: Contis | I17: Contis | J17: Contis | K17: Contis | L17: Contis | M17: Contis
C18: Number of Employees | D18: 1 | E18: 1 | F18: 1 | G18: 1 | H18: 1 | I18: 1 | J18: 1 | K18: 1 | L18: 1 | M18: 1
C19: Date & Time | D19: 45297 | E19: 45297 | F19: 45297 | G19: 45297 | H19: 45297 | I19: 45297 | J19: 45297 | K19: 45297 | L19: 45297 | M19: 45297
C22: Productivity per PALLET | N22: AVE
C23: PERFROMANCE RATING FACTOR % | D23: 1 | E23: 1 | F23: 1 | G23: 1 | H23: 1 | I23: 1 | J23: 1 | K23: 1 | L23: 1 | M23: 1
C24: ave.OBSERVED TIME(sec) | D24: =IFERROR((D10/D13)*D18,0) -> 275.73 | E24: =IFERROR((E10/E13)*E18,0) -> 183.55 | F24: =IFERROR((F10/F13)*F18,0) -> 220.1 | G24: =IFERROR((G10/G13)*G18,0) -> 253.19 | H24: =IFERROR((H10/H13)*H18,0) -> 176.19 | I24: =IFERROR((I10/I13)*I18,0) -> 179.18 | J24: =IFERROR((J10/J13)*J18,0) -> 174.91 | K24: =IFERROR((K10/K13)*K18,0) -> 165.75 | ... M24: =IFERROR((M10/M13)*M18,0) -> 156.34 | N24: =AVERAGE(D24:M24) -> 204.825
C25: NORMAL TIME = observed * PRF (sec) | D25: =D23*D24 -> 275.73 | E25: =E23*E24 -> 183.55 | F25: =F23*F24 -> 220.1 | G25: =G23*G24 -> 253.19 | H25: =H23*H24 -> 176.19 | I25: =I23*I24 -> 179.18 | J25: =J23*J24 -> 174.91 | K25: =K23*K24 -> 165.75 | ... M25: =M23*M24 -> 156.34 | N25: =AVERAGE(D25:M25) -> 204.825
C26: STANDARD TIME =Normal Time *[1+ Allowance Factor(5%)] | D26: =D25*(1+0.05) -> 289.5165 | E26: =E25*(1+0.05) -> 192.7275 | F26: =F25*(1+0.05) -> 231.105 | G26: =G25*(1+0.05) -> 265.8495 | H26: =H25*(1+0.05) -> 184.9995 | I26: =I25*(1+0.05) -> 188.139 | J26: =J25*(1+0.05) -> 183.6555 | K26: =K25*(1+0.05) -> 174.0375 | ... M26: =M25*(1+0.05) -> 164.157 | N26: =AVERAGE(D26:M26) -> 215.06625
C27: STANDARD PRODUCTIVITY PER MAN-HOUR | D27: =Iferror(3600/D26,0) -> 12.434524 | E27: =Iferror(3600/E26,0) -> 18.679223 | F27: =Iferror(3600/F26,0) -> 15.577335 | G27: =Iferror(3600/G26,0) -> 13.541496 | H27: =Iferror(3600/H26,0) -> 19.459512 | I27: =Iferror(3600/I26,0) -> 19.134789 | J27: =Iferror(3600/J26,0) -> 19.601918 | K27: =Iferror(3600/K26,0) -> 20.685197 | ... M27: =Iferror(3600/M26,0) -> 21.930225 | N27: =IFerror(3600/N26,0) -> 16.739028
C29: Productivity per BOX/PACK | N29: AVE
C30: ave.OBSERVED TIME(sec) | D30: =IFERROR((D10/D14)*D18,0) -> 0 | E30: =IFERROR((E10/E14)*E18,0) -> 0 | F30: =IFERROR((F10/F14)*F18,0) -> 0 | G30: =IFERROR((G10/G14)*G18,0) -> 0 | H30: =IFERROR((H10/H14)*H18,0) -> 0 | I30: =IFERROR((I10/I14)*I18,0) -> 0 | J30: =IFERROR((J10/J14)*J18,0) -> 0 | K30: =IFERROR((K10/K14)*K18,0) -> 0 | ... M30: =IFERROR((M10/M14)*M18,0) -> 0 | N30: =AVERAGE(D30:H30) -> 0
C31: NORMAL TIME = observed * PRF (sec) | D31: =D30*D23 -> 0 | E31: =E30*E23 -> 0 | F31: =F30*F23 -> 0 | G31: =G30*G23 -> 0 | H31: =H30*H23 -> 0 | I31: =I30*I23 -> 0 | J31: =J30*J23 -> 0 | K31: =K30*K23 -> 0 | ... M31: =M30*M23 -> 0 | N31: =AVERAGE(D31:H31) -> 0
C32: STANDARD TIME =Normal Time *[1+ Allowance Factor(5%)] | D32: =D31*(1+0.05) -> 0 | E32: =E31*(1+0.05) -> 0 | F32: =F31*(1+0.05) -> 0 | G32: =G31*(1+0.05) -> 0 | H32: =H31*(1+0.05) -> 0 | I32: =I31*(1+0.05) -> 0 | J32: =J31*(1+0.05) -> 0 | K32: =K31*(1+0.05) -> 0 | ... M32: =M31*(1+0.05) -> 0 | N32: =AVERAGE(D32:H32) -> 0
C33: STANDARD PRODUCTIVITY PER MAN-HOUR | D33: =Iferror(3600/D32,0) -> 0 | E33: =Iferror(3600/E32,0) -> 0 | F33: =Iferror(3600/F32,0) -> 0 | G33: =Iferror(3600/G32,0) -> 0 | H33: =Iferror(3600/H32,0) -> 0 | I33: =Iferror(3600/I32,0) -> 0 | J33: =Iferror(3600/J32,0) -> 0 | K33: =Iferror(3600/K32,0) -> 0 | ... N33: =Iferror(3600/N32,0) -> 0
C35: Productivity per ITEM | N35: AVE
C36: ave.OBSERVED TIME(sec) | D36: =IFERROR((D10/D15)*D18,0) -> 0.047953043 | E36: =IFERROR((E10/E15)*E18,0) -> 0.067981481 | F36: =IFERROR((F10/F15)*F18,0) -> 0.064735294 | G36: =IFERROR((G10/G15)*G18,0) -> 0.03164875 | H36: =IFERROR((H10/H15)*H18,0) -> 0.095237838 | I36: =IFERROR((I10/I15)*I18,0) -> 0.11945333 | J36: =IFERROR((J10/J15)*J18,0) -> 0.11660667 | K36: =IFERROR((K10/K15)*K18,0) -> 0.1105 | ... M36: =IFERROR((M10/M15)*M18,0) -> 0.10422667 | N36: =AVERAGE(D36:M36) -> 0.093388307
C37: NORMAL TIME = observed * PRF (sec) | D37: =D36*D23 -> 0.047953043 | E37: =E36*E23 -> 0.067981481 | F37: =F36*F23 -> 0.064735294 | G37: =G36*G23 -> 0.03164875 | H37: =H36*H23 -> 0.095237838 | I37: =I36*I23 -> 0.11945333 | J37: =J36*J23 -> 0.11660667 | K37: =K36*K23 -> 0.1105 | ... M37: =M36*M23 -> 0.10422667 | N37: =AVERAGE(D37:M37) -> 0.093388307
C38: STANDARD TIME =Normal Time *[1+ Allowance Factor(5%)] | D38: =D37*(1+0.05) -> 0.050350696 | E38: =E37*(1+0.05) -> 0.071380556 | F38: =F37*(1+0.05) -> 0.067972059 | G38: =G37*(1+0.05) -> 0.033231188 | H38: =H37*(1+0.05) -> 0.09999973 | I38: =I37*(1+0.05) -> 0.125426 | J38: =J37*(1+0.05) -> 0.122437 | K38: =K37*(1+0.05) -> 0.116025 | ... M38: =M37*(1+0.05) -> 0.109438 | N38: =AVERAGE(D38:M38) -> 0.098057723
C39: STANDARD PRODUCTIVITY PER MAN-HOUR | D39: =IFERROR(3600/D38,0) -> 71498.516 | E39: =IFERROR(3600/E38,0) -> 50433.903 | F39: =IFERROR(3600/F38,0) -> 52962.939 | G39: =IFERROR(3600/G38,0) -> 108331.97 | H39: =IFERROR(3600/H38,0) -> 36000.097 | I39: =IFERROR(3600/I38,0) -> 28702.183 | J39: =IFERROR(3600/J38,0) -> 29402.877 | K39: =IFERROR(3600/K38,0) -> 31027.796 | ... N39: =IFERROR(3600/N38,0) -> 36713.07
C41: Productivity per ITEM | N41: AVE
C42: ave.OBSERVED TIME(sec) | D42: =IFERROR((D10/D16)*D18,0) -> 91.91 | E42: =IFERROR((E10/E16)*E18,0) -> 183.55 | F42: =IFERROR((F10/F16)*F18,0) -> 110.05 | G42: =IFERROR((G10/G16)*G18,0) -> 84.396667 | H42: =IFERROR((H10/H16)*H18,0) -> 88.095 | I42: =IFERROR((I10/I16)*I18,0) -> 89.59 | J42: =IFERROR((J10/J16)*J18,0) -> 174.91 | K42: =IFERROR((K10/K16)*K18,0) -> 165.75 | ... M42: =IFERROR((M10/M16)*M18,0) -> 156.34 | N42: =AVERAGE(D42:M42) -> 140.79017
C43: NORMAL TIME = observed * PRF (sec) | D43: =D42*D23 -> 91.91 | E43: =E42*E29 -> 0 | F43: =F42*F29 -> 0 | G43: =G42*G29 -> 0 | H43: =H42*H29 -> 0 | I43: =I42*I29 -> 0 | J43: =J42*J29 -> 0 | K43: =K42*K29 -> 0 | L43: =L42*L29 -> 0 | M43: =M42*M29 -> 0 | N43: =AVERAGE(D43:M43) -> 9.191
C44: STANDARD TIME =Normal Time *[1+ Allowance Factor(5%)] | D44: =D43*(1+0.05) -> 96.5055 | E44: =E43*(1+0.05) -> 0 | F44: =F43*(1+0.05) -> 0 | G44: =G43*(1+0.05) -> 0 | H44: =H43*(1+0.05) -> 0 | I44: =I43*(1+0.05) -> 0 | J44: =J43*(1+0.05) -> 0 | K44: =K43*(1+0.05) -> 0 | ... M44: =M43*(1+0.05) -> 0 | N44: =AVERAGE(D44:M44) -> 9.65055
C45: STANDARD PRODUCTIVITY PER MAN-HOUR | D45: =IFERROR(3600/D44,0) -> 37.303573 | E45: =IFERROR(3600/E44,0) -> 0 | F45: =IFERROR(3600/F44,0) -> 0 | G45: =IFERROR(3600/G44,0) -> 0 | H45: =IFERROR(3600/H44,0) -> 0 | I45: =IFERROR(3600/I44,0) -> 0 | J45: =IFERROR(3600/J44,0) -> 0 | K45: =IFERROR(3600/K44,0) -> 0 | ... N45: =IFERROR(3600/N44,0) -> 373.03573

Sheet PUT-AWAY
B2: TIME AND MOTION STUDY SHEET
B3: Process being observed: | E3: Observer(s): | H3: DAY/TIME of observation: | K3: Name and Designation
B4: PUT-AWAY | E4: Hans David Wenceslao
B7: Step No. | C7: Elements | D7: OBSERVED TIMES (sec) | N7: Total Observed Time | P7: AVE | Q7: MAX | R7: WEIGHT PERCENTAGE | S7: Bottleneck | T7: Improvement
D8: T1 | E8: T2 | F8: T3 | G8: T4 | H8: T5 | I8: T6 | J8: T7 | K8: T8 | L8: T9 | M8: T10 | N8: (10 Trials)
B9: 1 | C9: Transfer to Location | D9: 76.48 | E9: 37.2 | F9: 42.69 | G9: 79.07 | H9: 51.35 | I9: 42.05 | J9: 39.36 | K9: 56 | L9: 46 | M9: 51.42 | N9: =SUM(D9:M9) -> 521.62 | P9: =Iferror(AVERAGE(D9:M9),0) -> 52.162 | Q9: =MAX(D9:M9) -> 79.07 | R9: =Iferror(P9/$P$11,0) -> 0.46991099 | T9: 5S
B10: 2 | C10: Fill-Up Put-away Form | D10: =38.22+24.38 -> 62.6 | E10: 48.36 | F10: 53.98 | G10: 44.88 | H10: 52.83 | I10: 60.07 | J10: 92.05 | K10: 56 | L10: 59 | M10: 58.65 | N10: =SUM(D10:M10) -> 588.42 | P10: =Iferror(AVERAGE(D10:M10),0) -> 58.842 | Q10: =MAX(D10:M10) -> 92.05 | R10: =Iferror(P10/$P$11,0) -> 0.53008901
C11: TOTAL Observed time (Sec) | D11: =sum(D9:D10) -> 139.08 | E11: =sum(E9:E10) -> 85.56 | F11: =sum(F9:F10) -> 96.67 | G11: =sum(G9:G10) -> 123.95 | H11: =sum(H9:H10) -> 104.18 | I11: =sum(I9:I10) -> 102.12 | J11: =sum(J9:J10) -> 131.41 | K11: =sum(K9:K10) -> 112 | ... M11: =sum(M9:M10) -> 110.07 | N11: =SUM(D11:M11) -> 1110.04 | P11: =SUM(P9:P10) -> 111.004 | Q11: =SUM(Q9:Q10) -> 171.12 | R11: =SUM(R9:R10) -> 1
C12: TOTAL Observed time (Min) | D12: =D11/60 -> 2.318 | E12: =E11/60 -> 1.426 | F12: =F11/60 -> 1.6111667 | G12: =G11/60 -> 2.0658333 | H12: =H11/60 -> 1.7363333 | I12: =I11/60 -> 1.702 | J12: =J11/60 -> 2.1901667 | K12: =K11/60 -> 1.8666667 | ... N12: =N11/60 -> 18.500667
N13: minutes
C14: Number of Pallet | D14: 1 | E14: 1 | F14: 1 | G14: 1 | H14: 1 | I14: 1 | J14: 1 | K14: 1 | L14: 1 | M14: 1
C15: Number of Boxes/Pack
C16: Number of Pcs | D16: 13000 | E16: 30000 | F16: 15000 | G16: 10000 | H16: 60 | I16: 222 | J16: 210 | K16: 50 | L16: 480 | M16: 480
C17: SKU | D17: PMRL | E17: PMRL | F17: PMRL | G17: PMRL | H17: PMRL | I17: PMRL | J17: PMRL | K17: PMRL | L17: PMRL | M17: PMRL
C18: Account & Brand | D18: CONTIS | E18: CONTIS | F18: CONTIS | G18: CONTIS | H18: CONTIS | I18: CONTIS | J18: CONTIS | K18: WENPHIL | L18: WENPHIL | M18: WENPHIL
C19: Number of Employees | D19: 1 | E19: 1 | F19: 1 | G19: 1 | H19: 1 | I19: 1 | J19: 1 | K19: 1 | L19: 1 | M19: 1
C20: Date & Time | D20: 45661 | E20: 45661 | F20: 45661 | G20: 45661 | H20: 45661 | I20: 45661 | J20: 45661 | K20: 45661 | L20: 45661 | M20: 45661
C23: Productivity per PALLET | N23: AVE
C24: PERFROMANCE RATING FACTOR % | D24: 1 | E24: 1 | F24: 1 | G24: 1 | H24: 1 | I24: 1 | J24: 1 | K24: 1 | L24: 1 | M24: 1
C25: ave.OBSERVED TIME(sec) | D25: =IFERROR((D11/D14)*D19,0) -> 139.08 | E25: =IFERROR((E11/E14)*E19,0) -> 85.56 | F25: =IFERROR((F11/F14)*F19,0) -> 96.67 | G25: 95 | H25: =IFERROR((H11/H14)*H19,0) -> 104.18 | I25: =IFERROR((I11/I14)*I19,0) -> 102.12 | J25: =IFERROR((J11/J14)*J19,0) -> 131.41 | K25: =IFERROR((K11/K14)*K19,0) -> 112 | L25: =IFERROR((L11/L14)*L19,0) -> 105 | M25: =IFERROR((M11/M14)*M19,0) -> 110.07 | N25: =AVERAGE(D25:M25) -> 108.109
C26: NORMAL TIME = observed * PRF (sec) | D26: =D24*D25 -> 139.08 | E26: =E24*E25 -> 85.56 | F26: =F24*F25 -> 96.67 | G26: =G24*G25 -> 95 | H26: =H24*H25 -> 104.18 | I26: =I24*I25 -> 102.12 | J26: =J24*J25 -> 131.41 | K26: =K24*K25 -> 112 | ... M26: =M24*M25 -> 110.07 | N26: =AVERAGE(D26:M26) -> 108.109
C27: STANDARD TIME =Normal Time *[1+ Allowance Factor(5%)+Machine Allowance (5%)] | D27: =D26*(1+0.1) -> 152.988 | E27: =E26*(1+0.1) -> 94.116 | F27: =F26*(1+0.1) -> 106.337 | G27: =G26*(1+0.1) -> 104.5 | H27: =H26*(1+0.1) -> 114.598 | I27: =I26*(1+0.1) -> 112.332 | J27: =J26*(1+0.1) -> 144.551 | K27: =K26*(1+0.1) -> 123.2 | ... M27: =M26*(1+0.1) -> 121.077 | N27: =AVERAGE(D27:M27) -> 118.9199
C28: STANDARD PRODUCTIVITY PER MAN-HOUR | D28: =Iferror(3600/D27,0) -> 23.531257 | E28: =Iferror(3600/E27,0) -> 38.250669 | F28: =Iferror(3600/F27,0) -> 33.854632 | G28: =Iferror(3600/G27,0) -> 34.449761 | H28: =Iferror(3600/H27,0) -> 31.414161 | I28: =Iferror(3600/I27,0) -> 32.047858 | J28: =Iferror(3600/J27,0) -> 24.904705 | K28: =Iferror(3600/K27,0) -> 29.220779 | ... M28: =Iferror(3600/M27,0) -> 29.733145 | N28: =IFerror(3600/N27,0) -> 30.272478
C30: Productivity per BOX/PACK | N30: AVE
C31: ave.OBSERVED TIME(sec) | D31: =IFERROR((D11/D15)*D19,0) -> 0 | E31: =IFERROR((E11/E15)*E19,0) -> 0 | F31: =IFERROR((F11/F15)*F19,0) -> 0 | G31: =IFERROR((G11/G15)*G19,0) -> 0 | H31: =IFERROR((H11/H15)*H19,0) -> 0 | I31: =IFERROR((I11/I15)*I19,0) -> 0 | J31: =IFERROR((J11/J15)*J19,0) -> 0 | K31: =IFERROR((K11/K15)*K19,0) -> 0 | ... M31: =IFERROR((M11/M15)*M19,0) -> 0 | N31: =AVERAGE(D31:H31) -> 0
C32: NORMAL TIME = observed * PRF (sec) | D32: =D31*D24 -> 0 | E32: =E31*E24 -> 0 | F32: =F31*F24 -> 0 | G32: =G31*G24 -> 0 | H32: =H31*H24 -> 0 | I32: =I31*I24 -> 0 | J32: =J31*J24 -> 0 | K32: =K31*K24 -> 0 | ... M32: =M31*M24 -> 0 | N32: =AVERAGE(D32:H32) -> 0
C33: STANDARD TIME =Normal Time *[1+ Allowance Factor(5%)] | D33: =D32*(1+0.05) -> 0 | E33: =E32*(1+0.05) -> 0 | F33: =F32*(1+0.05) -> 0 | G33: =G32*(1+0.05) -> 0 | H33: =H32*(1+0.05) -> 0 | I33: =I32*(1+0.05) -> 0 | J33: =J32*(1+0.05) -> 0 | K33: =K32*(1+0.05) -> 0 | ... M33: =M32*(1+0.05) -> 0 | N33: =AVERAGE(D33:H33) -> 0
C34: STANDARD PRODUCTIVITY PER MAN-HOUR | D34: =Iferror(3600/D33,0) -> 0 | E34: =Iferror(3600/E33,0) -> 0 | F34: =Iferror(3600/F33,0) -> 0 | G34: =Iferror(3600/G33,0) -> 0 | H34: =Iferror(3600/H33,0) -> 0 | I34: =Iferror(3600/I33,0) -> 0 | J34: =Iferror(3600/J33,0) -> 0 | K34: =Iferror(3600/K33,0) -> 0 | ... N34: =Iferror(3600/N33,0) -> 0
C36: Productivity per PCS | N36: AVE
C37: ave.OBSERVED TIME(sec) | D37: =IFERROR((D11/D16)*D19,0) -> 0.010698462 | E37: =IFERROR((E11/E16)*E19,0) -> 0.002852 | F37: =IFERROR((F11/F16)*F19,0) -> 0.0064446667 | G37: =IFERROR((G11/G16)*G19,0) -> 0.012395 | H37: =IFERROR((H11/H16)*H19,0) -> 1.7363333 | I37: =IFERROR((I11/I16)*I19,0) -> 0.46 | J37: =IFERROR((J11/J16)*J19,0) -> 0.6257619 | K37: =IFERROR((K11/K16)*K19,0) -> 2.24 | ... M37: =IFERROR((M11/M16)*M19,0) -> 0.2293125 | N37: =AVERAGE(D37:M37) -> 0.55425479 | O37: =N37*60 -> 33.255287
C38: NORMAL TIME = observed * PRF (sec) | D38: =D37*D24 -> 0.010698462 | E38: =E37*E24 -> 0.002852 | F38: =F37*F24 -> 0.0064446667 | G38: =G37*G24 -> 0.012395 | H38: =H37*H24 -> 1.7363333 | I38: =I37*I24 -> 0.46 | J38: =J37*J24 -> 0.6257619 | K38: =K37*K24 -> 2.24 | ... M38: =M37*M24 -> 0.2293125 | N38: =AVERAGE(D38:M38) -> 0.55425479
C39: STANDARD TIME =Normal Time *[1+ Allowance Factor(5%)+Machine Allowance (5%)] | D39: =D38*(1+0.1) -> 0.011768308 | E39: =E38*(1+0.1) -> 0.0031372 | F39: =F38*(1+0.1) -> 0.0070891333 | G39: =G38*(1+0.1) -> 0.0136345 | H39: =H38*(1+0.1) -> 1.9099667 | I39: =I38*(1+0.1) -> 0.506 | J39: =J38*(1+0.1) -> 0.6883381 | K39: =K38*(1+0.1) -> 2.464 | ... M39: =M38*(1+0.1) -> 0.25224375 | N39: =AVERAGE(D39:M39) -> 0.60968027
C40: STANDARD PRODUCTIVITY PER MAN-HOUR | D40: =IFERROR(3600/D39,0) -> 305906.35 | E40: =IFERROR(3600/E39,0) -> 1147520.1 | F40: =IFERROR(3600/F39,0) -> 507819.48 | G40: =IFERROR(3600/G39,0) -> 264036.08 | H40: =IFERROR(3600/H39,0) -> 1884.8496 | I40: =IFERROR(3600/I39,0) -> 7114.6245 | J40: =IFERROR(3600/J39,0) -> 5229.988 | K40: =IFERROR(3600/K39,0) -> 1461.039 | ... N40: =IFERROR(3600/N39,0) -> 5904.7343

Sheet PICKING
B2: TIME AND MOTION STUDY SHEET
B3: Process being observed: | E3: Observer(s): | H3: DAY/TIME of observation: | K3: Name and Designation
B4: PICKING | E4: Hans David Wenceslao
B7: Step No. | C7: Elements | D7: OBSERVED TIMES (sec) | N7: Total Observed Time | P7: AVE | Q7: MAX | R7: WEIGHT PERCENTAGE | S7: Bottleneck | T7: Improvement
D8: T1 | E8: T2 | F8: T3 | G8: T4 | H8: T5 | I8: T6 | J8: T7 | K8: T8 | L8: T9 | M8: T10 | N8: (10 Trials)
B9: 1 | C9: Finding Pallet | D9: 78.02 | E9: 21.37 | F9: 19.51 | G9: 36.02 | H9: 26.18 | N9: =SUM(D9:H9) -> 181.1 | P9: =AVERAGE(D9:M9) -> 36.22 | Q9: =MAX(D9:M9) -> 78.02 | R9: =P9/$P$12 -> 0.048859056
B10: 2 | C10: Picking | D10: 1388.08 | E10: 235.26 | F10: 225.94 | G10: 487.7 | H10: 921.6 | P10: =AVERAGE(D10:M10) -> 651.716 | Q10: =MAX(D10:M10) -> 1388.08 | R10: =P10/$P$12 -> 0.87913386
B11: 3 | C11: Transport to Staging | D11: 107.98 | E11: 31.64 | F11: 29.32 | G11: 51.46 | H11: 46.5 | P11: =AVERAGE(D11:M11) -> 53.38 | Q11: =MAX(D11:M11) -> 107.98 | R11: =P11/$P$12 -> 0.072007079
C12: TOTAL Observed time (Sec) | D12: =sum(D9:D11) -> 1574.08 | E12: =sum(E9:E11) -> 288.27 | F12: =sum(F9:F11) -> 274.77 | G12: =sum(G9:G11) -> 575.18 | H12: =sum(H9:H11) -> 994.28 | I12: =sum(I9:I11) -> 0 | J12: =sum(J9:J11) -> 0 | K12: =sum(K9:K11) -> 0 | ... M12: =sum(M9:M11) -> 0 | N12: =SUM(D12:H12) -> 3706.58 | O12: TOTAL | P12: =SUM(P9:P11) -> 741.316 | Q12: =MAX(Q9:Q11) -> 1388.08 | R12: =SUM(R9) -> 0.048859056
C13: TOTAL Observed time (Min) | D13: =D12/60 -> 26.234667 | E13: =E12/60 -> 4.8045 | F13: =F12/60 -> 4.5795 | G13: =G12/60 -> 9.5863333 | H13: =H12/60 -> 16.571333 | I13: =I12/60 -> 0 | J13: =J12/60 -> 0 | K13: =K12/60 -> 0 | ... N13: =N12/60 -> 61.776333
N14: minutes
C15: Number of Pallet | D15: 3 | E15: 1 | F15: 1 | G15: 2 | H15: 1
C16: Number of Picklist | D16: 1 | E16: 1 | F16: 1 | G16: 3 | H16: 2
C17: Number of Items | D17: 14228 | E17: 10 | F17: 28 | G17: 143 | H17: 4650 | N17: =AVERAGE(D17:H17) -> 3811.8
C18: SKU | D18: PMRL | E18: PMRL | F18: PMRL | G18: PMRL | H18: PMRL
C19: Account & Brand | D19: Contis
C20: Number of Employees | D20: 1 | E20: 1 | F20: 1 | G20: 1 | H20: 1
C21: Date & Time | D21: 45661 | E21: 45661 | F21: 45661 | G21: 45672 | H21: 45672
C24: Productivity per PALLET | N24: AVE
C25: PERFROMANCE RATING FACTOR % | D25: 1 | E25: 0.6 | F25: 0.7 | G25: 0.7 | H25: 0.7 | I25: 0.7 | J25: 0.7 | K25: 1 | L25: 1 | M25: 1
C26: ave.OBSERVED TIME(sec) | D26: =IFERROR((D12/D15)*D20,0) -> 524.69333 | E26: =IFERROR((E12/E15)*E20,0) -> 288.27 | F26: =IFERROR((F12/F15)*F20,0) -> 274.77 | G26: =IFERROR((G12/G15)*G20,0) -> 287.59 | H26: =IFERROR((H12/H15)*H20,0) -> 994.28 | I26: =IFERROR((I12/I15)*I20,0) -> 0 | J26: =IFERROR((J12/J15)*J20,0) -> 0 | K26: =IFERROR((K12/K15)*K20,0) -> 0 | ... M26: =IFERROR((M12/M15)*M20,0) -> 0 | N26: =AVERAGE(D26:H26) -> 473.92067
C27: NORMAL TIME = observed * PRF (sec) | D27: =D25*D26 -> 524.69333 | E27: =E25*E26 -> 172.962 | F27: =F25*F26 -> 192.339 | G27: =G25*G26 -> 201.313 | H27: =H25*H26 -> 695.996 | I27: =I25*I26 -> 0 | J27: =J25*J26 -> 0 | K27: =K25*K26 -> 0 | ... M27: =M25*M26 -> 0 | N27: =AVERAGE(D27:H27) -> 357.46067
C28: STANDARD TIME =Normal Time *[1+ Allowance Factor(5%)] | D28: =D27*(1+0.05) -> 550.928 | E28: =E27*(1+0.05) -> 181.6101 | F28: =F27*(1+0.05) -> 201.95595 | G28: =G27*(1+0.05) -> 211.37865 | H28: =H27*(1+0.05) -> 730.7958 | I28: =I27*(1+0.05) -> 0 | J28: =J27*(1+0.05) -> 0 | K28: =K27*(1+0.05) -> 0 | ... M28: =M27*(1+0.05) -> 0 | N28: =AVERAGE(D28:H28) -> 375.3337
C29: STANDARD PRODUCTIVITY PER MAN-HOUR | D29: =Iferror(3600/D28,0) -> 6.5344292 | E29: =Iferror(3600/E28,0) -> 19.822686 | F29: =Iferror(3600/F28,0) -> 17.825669 | G29: =Iferror(3600/G28,0) -> 17.031048 | H29: =Iferror(3600/H28,0) -> 4.9261367 | I29: =Iferror(3600/I28,0) -> 0 | J29: =Iferror(3600/J28,0) -> 0 | K29: =Iferror(3600/K28,0) -> 0 | ... M29: =Iferror(3600/M28,0) -> 0 | N29: =IFerror(3600/N28,0) -> 9.5914649
C31: Productivity per PICKLIST | N31: AVE
C32: ave.OBSERVED TIME(sec) | D32: =IFERROR((D12/D16)*D20,0) -> 1574.08 | E32: =IFERROR((E12/E16)*E20,0) -> 288.27 | F32: =IFERROR((F12/F16)*F20,0) -> 274.77 | G32: =IFERROR((G12/G16)*G20,0) -> 191.72667 | H32: =IFERROR((H12/H16)*H20,0) -> 497.14 | I32: =IFERROR((I12/I16)*I20,0) -> 0 | J32: =IFERROR((J12/J16)*J20,0) -> 0 | K32: =IFERROR((K12/K16)*K20,0) -> 0 | ... M32: =IFERROR((M12/M16)*M20,0) -> 0 | N32: =AVERAGE(D32:H32) -> 565.19733
C33: NORMAL TIME = observed * PRF (sec) | D33: =D32*D25 -> 1574.08 | E33: =E32*E25 -> 172.962 | F33: =F32*F25 -> 192.339 | G33: =G32*G25 -> 134.20867 | H33: =H32*H25 -> 347.998 | I33: =I32*I25 -> 0 | J33: =J32*J25 -> 0 | K33: =K32*K25 -> 0 | ... M33: =M32*M25 -> 0 | N33: =AVERAGE(D33:H33) -> 484.31753
C34: STANDARD TIME =Normal Time *[1+ Allowance Factor(5%)] | D34: =D33*(1+0.05) -> 1652.784 | E34: =E33*(1+0.05) -> 181.6101 | F34: =F33*(1+0.05) -> 201.95595 | G34: =G33*(1+0.05) -> 140.9191 | H34: =H33*(1+0.05) -> 365.3979 | I34: =I33*(1+0.05) -> 0 | J34: =J33*(1+0.05) -> 0 | K34: =K33*(1+0.05) -> 0 | ... M34: =M33*(1+0.05) -> 0 | N34: =AVERAGE(D34:H34) -> 508.53341
C35: STANDARD PRODUCTIVITY PER MAN-HOUR | D35: =Iferror(3600/D34,0) -> 2.1781431 | E35: =Iferror(3600/E34,0) -> 19.822686 | F35: =Iferror(3600/F34,0) -> 17.825669 | G35: =Iferror(3600/G34,0) -> 25.546572 | H35: =Iferror(3600/H34,0) -> 9.8522734 | I35: =Iferror(3600/I34,0) -> 0 | J35: =Iferror(3600/J34,0) -> 0 | K35: =Iferror(3600/K34,0) -> 0 | ... N35: =Iferror(3600/N34,0) -> 7.0791809
C37: Productivity per ITEM | N37: AVE
C38: ave.OBSERVED TIME(sec) | D38: =IFERROR((D12/D17)*D20,0) -> 0.11063256 | E38: =IFERROR((E12/E17)*E20,0) -> 28.827 | F38: =IFERROR((F12/F17)*F20,0) -> 9.8132143 | G38: =IFERROR((G12/G17)*G20,0) -> 4.0222378 | H38: =IFERROR((H12/H17)*H20,0) -> 0.21382366 | I38: =IFERROR((I12/I17)*I20,0) -> 0 | J38: =IFERROR((J12/J17)*J20,0) -> 0 | K38: =IFERROR((K12/K17)*K20,0) -> 0 | ... M38: =IFERROR((M12/M17)*M20,0) -> 0 | N38: =AVERAGE(D38:H38) -> 8.5973817
C39: NORMAL TIME = observed * PRF (sec) | D39: =D38*D25 -> 0.11063256 | E39: =E38*E25 -> 17.2962 | F39: =F38*F25 -> 6.86925 | G39: =G38*G25 -> 2.8155664 | H39: =H38*H25 -> 0.14967656 | I39: =I38*I25 -> 0 | J39: =J38*J25 -> 0 | K39: =K38*K25 -> 0 | ... M39: =M38*M25 -> 0 | N39: =AVERAGE(D39:H39) -> 5.4482651
C40: STANDARD TIME =Normal Time *[1+ Allowance Factor(5%)] | D40: =D39*(1+0.05) -> 0.11616418 | E40: =E39*(1+0.05) -> 18.16101 | F40: =F39*(1+0.05) -> 7.2127125 | G40: =G39*(1+0.05) -> 2.9563448 | H40: =H39*(1+0.05) -> 0.15716039 | I40: =I39*(1+0.05) -> 0 | J40: =J39*(1+0.05) -> 0 | K40: =K39*(1+0.05) -> 0 | ... M40: =M39*(1+0.05) -> 0 | N40: =AVERAGE(D40:H40) -> 5.7206784
C41: STANDARD PRODUCTIVITY PER MAN-HOUR | D41: =IFERROR(3600/D40,0) -> 30990.619 | E41: =IFERROR(3600/E40,0) -> 198.22686 | F41: =IFERROR(3600/F40,0) -> 499.11874 | G41: =IFERROR(3600/G40,0) -> 1217.72 | H41: =IFERROR(3600/H40,0) -> 22906.536 | I41: =IFERROR(3600/I40,0) -> 0 | J41: =IFERROR(3600/J40,0) -> 0 | K41: =IFERROR(3600/K40,0) -> 0 | ... N41: =IFERROR(3600/N40,0) -> 629.296
B44: TIME AND MOTION STUDY SHEET
B45: Process being observed: | E45: Observer(s): | H45: DAY/TIME of observation: | K45: Name and Designation
B46: PICKING | E46: Hans David Wenceslao
B49: Step No. | C49: Elements | D49: OBSERVED TIMES (sec) | N49: Total Observed Time | P49: AVE | Q49: MAX | R49: WEIGHT PERCENTAGE | S49: Bottleneck | T49: Improvement
D50: T1 | E50: T2 | F50: T3 | G50: T4 | H50: T5 | I50: T6 | J50: T7 | K50: T8 | L50: T9 | M50: T10 | N50: (10 Trials)
B51: 1 | C51: Finding Pallet | D51: 40.39 | E51: 47.24 | F51: 36.28 | G51: 90.52 | N51: =SUM(D51:H51) -> 214.43 | P51: =AVERAGE(D51:M51) -> 53.6075 | Q51: =MAX(D51:M51) -> 90.52 | R51: =P51/$P$12 -> 0.072313966
...

Sheet OUTBOUND CHECKING
B2: TIME AND MOTION STUDY SHEET
B3: Process being observed: | E3: Observer(s): | H3: DAY/TIME of observation: | K3: Name and Designation
B4: OUTBOUND | E4: Hans David Wenceslao
B7: Step No. | C7: Elements | D7: OBSERVED TIMES (sec) | N7: Total Observed Time | P7: AVE | Q7: MAX | R7: WEIGHT PERCENTAGE | S7: Bottleneck | T7: Improvement
D8: T1 | E8: T2 | F8: T3 | G8: T4 | H8: T5 | I8: T6 | J8: T7 | K8: T8 | L8: T9 | M8: T10 | N8: (10 Trials)
B9: 2 | C9: Checking | D9: 134.19 | E9: 263.92 | F9: 95.77 | G9: 215.45 | H9: 488.19 | I9: 293.6 | J9: 236.89 | K9: 260.67 | L9: 118.11 | M9: 269.07 | N9: =SUM(D9:H9) -> 1197.52 | P9: =AVERAGE(D9:M9) -> 237.586 | Q9: =MAX(D9:M9) -> 488.19 | R9: =P9/$P$10 -> 1 | T9: Check in Staging Area then Transport to Docking Area
C10: TOTAL Observed time (Sec) | D10: =sum(D9) -> 134.19 | E10: =sum(E9) -> 263.92 | F10: =sum(F9) -> 95.77 | G10: =sum(G9) -> 215.45 | H10: =sum(H9) -> 488.19 | I10: =sum(I9) -> 293.6 | J10: =sum(J9) -> 236.89 | K10: =sum(K9) -> 260.67 | ... M10: =sum(M9) -> 269.07 | N10: =SUM(D10:H10) -> 1197.52 | O10: TOTAL | P10: =SUM(P9) -> 237.586 | Q10: =SUM(Q9) -> 488.19 | R10: =SUM(R9) -> 1
C11: TOTAL Observed time (Min) | D11: =D10/60 -> 2.2365 | E11: =E10/60 -> 4.3986667 | F11: =F10/60 -> 1.5961667 | G11: =G10/60 -> 3.5908333 | H11: =H10/60 -> 8.1365 | I11: =I10/60 -> 4.8933333 | J11: =J10/60 -> 3.9481667 | K11: =K10/60 -> 4.3445 | ... N11: =N10/60 -> 19.958667
N12: minutes
C13: Number of Pallet | D13: 1 | E13: 1 | F13: 1 | G13: 2 | H13: 4 | I13: 1 | J13: 2 | K13: 2 | L13: 1 | M13: 3
C14: Number of Boxes/Pack
C15: Number of Items | D15: 338 | E15: 705 | F15: 15 | G15: 272 | H15: 140 | I15: 256 | J15: 7038 | K15: 8259 | L15: 5503 | M15: 8502
C16: SKU | D16: PMRL | E16: PMRL | F16: PMRL | G16: PMRL | H16: PMRL | I16: PMRL | J16: PMRL | K16: PMRL | L16: PMRL | M16: PMRL
C17: Account & Brand | D17: MASUMA | E17: MASUMA | F17: MASUMA | G17: MASUMA | H17: MASUMA | I17: MASUMA | J17: MASUMA | K17: MASUMA | L17: MASUMA | M17: MASUMA
C18: Number of Employees | D18: 2 | E18: 2 | F18: 2 | G18: 2 | H18: 2 | I18: 2 | J18: 2 | K18: 2 | L18: 2 | M18: 2
C19: Date & Time | D19: 45663 | E19: 45664 | F19: 45664 | G19: 45664 | H19: 45664 | I19: 45664
C22: Productivity per PALLET | N22: AVE
C23: PERFROMANCE RATING FACTOR % | D23: 1 | E23: 1 | F23: 1 | G23: 1 | H23: 1 | I23: 1 | J23: 1 | K23: 1 | L23: 1 | M23: 1
C24: ave.OBSERVED TIME(sec) | D24: =IFERROR((D10/D13)*D18,0) -> 268.38 | E24: =IFERROR((E10/E13)*E18,0) -> 527.84 | F24: =IFERROR((F10/F13)*F18,0) -> 191.54 | G24: =IFERROR((G10/G13)*G18,0) -> 215.45 | H24: =IFERROR((H10/H13)*H18,0) -> 244.095 | I24: =IFERROR((I10/I13)*I18,0) -> 587.2 | J24: =IFERROR((J10/J13)*J18,0) -> 236.89 | K24: =IFERROR((K10/K13)*K18,0) -> 260.67 | ... M24: =IFERROR((M10/M13)*M18,0) -> 179.38 | N24: =AVERAGE(D24:M24) -> 294.7665
C25: NORMAL TIME = observed * PRF (sec) | D25: =D23*D24 -> 268.38 | E25: =E23*E24 -> 527.84 | F25: =F23*F24 -> 191.54 | G25: =G23*G24 -> 215.45 | H25: =H23*H24 -> 244.095 | I25: =I23*I24 -> 587.2 | J25: =J23*J24 -> 236.89 | K25: =K23*K24 -> 260.67 | ... M25: =M23*M24 -> 179.38 | N25: =AVERAGE(D25:M25) -> 294.7665
C26: STANDARD TIME =Normal Time *[1+ Allowance Factor(5%)] | D26: =D25*(1+0.05) -> 281.799 | E26: =E25*(1+0.05) -> 554.232 | F26: =F25*(1+0.05) -> 201.117 | G26: =G25*(1+0.05) -> 226.2225 | H26: =H25*(1+0.05) -> 256.29975 | I26: =I25*(1+0.05) -> 616.56 | J26: =J25*(1+0.05) -> 248.7345 | K26: =K25*(1+0.05) -> 273.7035 | ... M26: =M25*(1+0.05) -> 188.349 | N26: =AVERAGE(D26:M26) -> 309.50482
C27: STANDARD PRODUCTIVITY PER MAN-HOUR | D27: =Iferror(3600/D26,0) -> 12.775063 | E27: =Iferror(3600/E26,0) -> 6.4954748 | F27: =Iferror(3600/F26,0) -> 17.900028 | G27: =Iferror(3600/G26,0) -> 15.913536 | H27: =Iferror(3600/H26,0) -> 14.046053 | I27: =Iferror(3600/I26,0) -> 5.8388478 | J27: =Iferror(3600/J26,0) -> 14.473264 | K27: =Iferror(3600/K26,0) -> 13.152919 | ... M27: =Iferror(3600/M26,0) -> 19.113454 | N27: =IFerror(3600/N26,0) -> 11.631483
C29: Productivity per BOX/PACK | N29: AVE
C30: ave.OBSERVED TIME(sec) | D30: =IFERROR((D10/D14)*D18,0) -> 0 | E30: =IFERROR((E10/E14)*E18,0) -> 0 | F30: =IFERROR((F10/F14)*F18,0) -> 0 | G30: =IFERROR((G10/G14)*G18,0) -> 0 | H30: =IFERROR((H10/H14)*H18,0) -> 0 | I30: =IFERROR((I10/I14)*I18,0) -> 0 | J30: =IFERROR((J10/J14)*J18,0) -> 0 | K30: =IFERROR((K10/K14)*K18,0) -> 0 | ... M30: =IFERROR((M10/M14)*M18,0) -> 0 | N30: =AVERAGE(D30:H30) -> 0
C31: NORMAL TIME = observed * PRF (sec) | D31: =D30*D23 -> 0 | E31: =E30*E23 -> 0 | F31: =F30*F23 -> 0 | G31: =G30*G23 -> 0 | H31: =H30*H23 -> 0 | I31: =I30*I23 -> 0 | J31: =J30*J23 -> 0 | K31: =K30*K23 -> 0 | ... M31: =M30*M23 -> 0 | N31: =AVERAGE(D31:H31) -> 0
C32: STANDARD TIME =Normal Time *[1+ Allowance Factor(5%)] | D32: =D31*(1+0.05) -> 0 | E32: =E31*(1+0.05) -> 0 | F32: =F31*(1+0.05) -> 0 | G32: =G31*(1+0.05) -> 0 | H32: =H31*(1+0.05) -> 0 | I32: =I31*(1+0.05) -> 0 | J32: =J31*(1+0.05) -> 0 | K32: =K31*(1+0.05) -> 0 | ... M32: =M31*(1+0.05) -> 0 | N32: =AVERAGE(D32:H32) -> 0
C33: STANDARD PRODUCTIVITY PER MAN-HOUR | D33: =Iferror(3600/D32,0) -> 0 | E33: =Iferror(3600/E32,0) -> 0 | F33: =Iferror(3600/F32,0) -> 0 | G33: =Iferror(3600/G32,0) -> 0 | H33: =Iferror(3600/H32,0) -> 0 | I33: =Iferror(3600/I32,0) -> 0 | J33: =Iferror(3600/J32,0) -> 0 | K33: =Iferror(3600/K32,0) -> 0 | ... N33: =Iferror(3600/N32,0) -> 0
C35: Productivity per ITEM | N35: AVE
C36: ave.OBSERVED TIME(sec) | D36: =IFERROR((D10/D15)*D18,0) -> 0.79402367 | E36: =IFERROR((E10/E15)*E18,0) -> 0.74870922 | F36: =IFERROR((F10/F15)*F18,0) -> 12.769333 | G36: =IFERROR((G10/G15)*G18,0) -> 1.5841912 | H36: =IFERROR((H10/H15)*H18,0) -> 6.9741429 | I36: =IFERROR((I10/I15)*I18,0) -> 2.29375 | J36: =IFERROR((J10/J15)*J18,0) -> 0.06731742 | K36: =IFERROR((K10/K15)*K18,0) -> 0.063123865 | ... M36: =IFERROR((M10/M15)*M18,0) -> 0.063295695 | N36: =AVERAGE(D36:M36) -> 2.5400813
C37: NORMAL TIME = observed * PRF (sec) | D37: =D36*D23 -> 0.79402367 | E37: =E36*E23 -> 0.74870922 | F37: =F36*F23 -> 12.769333 | G37: =G36*G23 -> 1.5841912 | H37: =H36*H23 -> 6.9741429 | I37: =I36*I23 -> 2.29375 | J37: =J36*J23 -> 0.06731742 | K37: =K36*K23 -> 0.063123865 | ... M37: =M36*M23 -> 0.063295695 | N37: =AVERAGE(D37:M37) -> 2.5400813
C38: STANDARD TIME =Normal Time *[1+ Allowance Factor(5%)] | D38: =D37*(1+0.05) -> 0.83372485 | E38: =E37*(1+0.05) -> 0.78614468 | F38: =F37*(1+0.05) -> 13.4078 | G38: =G37*(1+0.05) -> 1.6634007 | H38: =H37*(1+0.05) -> 7.32285 | I38: =I37*(1+0.05) -> 2.4084375 | J38: =J37*(1+0.05) -> 0.070683291 | K38: =K37*(1+0.05) -> 0.066280058 | ... M38: =M37*(1+0.05) -> 0.06646048 | N38: =AVERAGE(D38:M38) -> 2.6670854
C39: STANDARD PRODUCTIVITY PER MAN-HOUR | D39: =IFERROR(3600/D38,0) -> 4317.9713 | E39: =IFERROR(3600/E38,0) -> 4579.3097 | F39: =IFERROR(3600/F38,0) -> 268.50043 | G39: =IFERROR(3600/G38,0) -> 2164.241 | H39: =IFERROR(3600/H38,0) -> 491.61187 | I39: =IFERROR(3600/I38,0) -> 1494.745 | J39: =IFERROR(3600/J38,0) -> 50931.415 | K39: =IFERROR(3600/K38,0) -> 54314.98 | ... N39: =IFERROR(3600/N38,0) -> 1349.7881

Sheet 10. QUALITY CHECKING
B2: TIME AND MOTION STUDY SHEET
B3: Process being observed: | E3: Observer(s): | H3: DAY/TIME of observation: | K3: Name and Designation
B4: Quality Checking (Manual Checking) - HJ | E4: Hans David Wenceslao & Nichole Jean Necio
B7: Step No. | C7: Elements | D7: OBSERVED TIMES (sec) | N7: Total Observed Time | P7: AVE | Q7: MAX | R7: WEIGHT PERCENTAGE | S7: Bottleneck | T7: Improvement
D8: TRIAL 1 | E8: TRIAL 2 | F8: TRIAL 3 | G8: TRIAL 4 | H8: TRIAL 5 | I8: TRIAL 6 | J8: TRIAL 7 | K8: TRIAL 8 | L8: TRIAL 9 | M8: TRIAL 10 | N8: (10trial)
B9: 1 | C9: Checking Items According to the Picklist -(PO,Name of Customers,SKU of item,Quantity,Sign the Picklist) -Transfer Basket to Q.C 3 | D9: 15.02 | E9: 12.1 | F9: 15.05 | G9: 8.29 | H9: 9.59 | I9: 7.61 | J9: 10.81 | K9: 24.04 | L9: 23.08 | M9: 17.27 | N9: =SUM(D9:M9) -> 142.86 | P9: =AVERAGE(D9:M9) -> 14.286 | Q9: =MAX(D9:M9) -> 24.04 | R9: =P9/$P$10 -> 1 | S9: Overloaded area causes worker to stop and rearrange baskets | T9: Automated Q.C. like in Hatio can lessen the process of checking orders, it also decreases workers need for the QC and we can assigned them to other process like in packing or picking
C10: TOTAL Observed time (Sec) | D10: =SUM(D9) -> 15.02 | E10: =SUM(E9) -> 12.1 | F10: =SUM(F9) -> 15.05 | G10: =SUM(G9) -> 8.29 | H10: =SUM(H9) -> 9.59 | I10: =SUM(I9) -> 7.61 | J10: =SUM(J9) -> 10.81 | K10: =SUM(K9) -> 24.04 | ... M10: =SUM(M9) -> 17.27 | N10: =SUM(D10:H10) -> 60.05 | O10: TOTAL | P10: =SUM(P9) -> 14.286 | Q10: =SUM(Q9) -> 24.04 | R10: =R9 -> 1
N11: =N10/60 -> 1.0008333
N12: minutes
C13: Order reference number | D13: 652769168817375 | E13: 648731037520411 | F13: PO-6538827051611201 | G13: 653929725248761 | H13: 649679077606601 | I13: 655153182002076 | J13: 651201421711830 | K13: 651417238599737 | L13: 655621515727965 | M13: 651527644528572
C14: Number of Item(s) | D14: 5 | E14: 2 | F14: 4 | G14: 2 | H14: 2 | I14: 6 | J14: 2 | K14: 4 | L14: 2 | M14: 2
C15: Number of Order | D15: 1 | E15: 1 | F15: 1 | G15: 1 | H15: 1 | I15: 1 | J15: 1 | K15: 1 | L15: 1 | M15: 1
C16: Account & Brand | D16: High Jump | NIVEA | E16: High Jump | NIVEA | F16: High Jump | NIVEA | G16: High Jump | NIVEA | H16: High Jump | NIVEA | I16: High Jump | NIVEA | J16: High Jump | NIVEA | K16: High Jump | NIVEA | L16: High Jump | NIVEA | M16: High Jump | NIVEA
C17: Employee Name | D17: Christine Claire Alvarez | E17: Christine Claire Alvarez | F17: Kirsten Ann Delaisla | G17: Kirsten Ann Delaisla | H17: JC | I17: Jashtine Marie Pabillar | J17: Jashtine Marie Pabillar | K17: Casimira Cubilla | L17: Casimira Cubilla | M17: Casimira Cubilla
C18: Note/Cause of delay | E18: *Double Checking Items | F18: *Change Item | H18: *Recheck Items | J18: *Recheck Items *Adjust Bins | K18: *Change Item | L18: *Recheck Items
C19: Date & Time | D19: 05/23/23 | 1035H | E19: 05/23/23 | 1036H | F19: 05/25/23 | 1056H | G19: 05/25/23 | 1057H | H19: 05/25/23 | 1120H | I19: 05/29/23 | 1117H | J19: 05/29/23 | 1118H | K19: 05/29/23 | 1602H | L19: 05/29/23 | 1603 | M19: 05/29/23 | 1605
C21: PRODUCTIVITY PER ORDER/WAYBILL | N21: AVE
C22: PERFROMANCE RATING FACTOR % | D22: 1 | E22: 1 | F22: 1 | G22: 2 | H22: 1.5 | I22: 2 | J22: 1.5 | K22: 1 | L22: 1 | M22: 1 | N22: =AVERAGE(D22:M22) -> 1.3
C23: ave.OBSERVED TIME(sec) | D23: =D$10/D15 -> 15.02 | E23: =E$10/E15 -> 12.1 | F23: =F$10/F15 -> 15.05 | G23: =G$10/G15 -> 8.29 | H23: =H$10/H15 -> 9.59 | I23: =I$10/I15 -> 7.61 | J23: =J$10/J15 -> 10.81 | K23: =K$10/K15 -> 24.04 | ... M23: =M$10/M15 -> 17.27 | N23: =AVERAGE(D23:M23) -> 14.286
C24: NORMAL TIME = observed * PRF (sec) | D24: =D23*D$22 -> 15.02 | E24: =E23*E$22 -> 12.1 | F24: =F23*F$22 -> 15.05 | G24: =G23*G$22 -> 16.58 | H24: =H23*H$22 -> 14.385 | I24: =I23*I$22 -> 15.22 | J24: =J23*J$22 -> 16.215 | K24: =K23*K$22 -> 24.04 | ... M24: =M23*M$22 -> 17.27 | N24: =AVERAGE(D24:M24) -> 16.896
C25: STANDARD TIME =Normal Time *[1+ Allowance Factor(5%)] | D25: =D24*(1+0.05) -> 15.771 | E25: =E24*(1+0.05) -> 12.705 | F25: =F24*(1+0.05) -> 15.8025 | G25: =G24*(1+0.05) -> 17.409 | H25: =H24*(1+0.05) -> 15.10425 | I25: =I24*(1+0.05) -> 15.981 | J25: =J24*(1+0.05) -> 17.02575 | K25: =K24*(1+0.05) -> 25.242 | ... M25: =M24*(1+0.05) -> 18.1335 | N25: =AVERAGE(D25:M25) -> 17.7408
C26: STANDARD PRODUCTIVITY PER MAN-HOUR | D26: =3600/D25 -> 228.26707 | E26: =3600/E25 -> 283.35301 | F26: =3600/F25 -> 227.81206 | G26: =3600/G25 -> 206.78959 | H26: =3600/H25 -> 238.34351 | I26: =3600/I25 -> 225.26751 | J26: =3600/J25 -> 211.44443 | K26: =3600/K25 -> 142.61944 | ... N26: =3600/N25 -> 202.92208
C28: PRODUCTIVITY PER ITEM | N28: AVE
C29: ave.OBSERVED TIME(sec) | D29: =D$10/D$14 -> 3.004 | E29: =E$10/E$14 -> 6.05 | F29: =F$10/F$14 -> 3.7625 | G29: =G$10/G$14 -> 4.145 | H29: =H$10/H$14 -> 4.795 | I29: =I$10/I$14 -> 1.2683333 | J29: =J$10/J$14 -> 5.405 | K29: =K$10/K$14 -> 6.01 | ... M29: =M$10/M$14 -> 8.635 | N29: =AVERAGE(D29:M29) -> 5.4614833
C30: NORMAL TIME = observed * PRF (sec) | D30: =D29*D$22 -> 3.004 | E30: =E29*E$22 -> 6.05 | F30: =F29*F$22 -> 3.7625 | G30: =G29*G$22 -> 8.29 | H30: =H29*H$22 -> 7.1925 | I30: =I29*I$22 -> 2.5366667 | J30: =J29*J$22 -> 8.1075 | K30: =K29*K$22 -> 6.01 | ... M30: =M29*M$22 -> 8.635 | N30: =AVERAGE(D30:M30) -> 6.5128167
C31: STANDARD TIME =Normal Time *[1+ Allowance Factor(5%)] | D31: =D30*(1+0.05) -> 3.1542 | E31: =E30*(1+0.05) -> 6.3525 | F31: =F30*(1+0.05) -> 3.950625 | G31: =G30*(1+0.05) -> 8.7045 | H31: =H30*(1+0.05) -> 7.552125 | I31: =I30*(1+0.05) -> 2.6635 | J31: =J30*(1+0.05) -> 8.512875 | K31: =K30*(1+0.05) -> 6.3105 | ... M31: =M30*(1+0.05) -> 9.06675 | N31: =AVERAGE(D31:M31) -> 6.8384575
C32: STANDARD PRODUCTIVITY PER MAN-HOUR | D32: =3600/D31 -> 1141.3354 | E32: =3600/E31 -> 566.70602 | F32: =3600/F31 -> 911.24822 | G32: =3600/G31 -> 413.57918 | H32: =3600/H31 -> 476.68703 | I32: =3600/I31 -> 1351.605 | J32: =3600/J31 -> 422.88886 | K32: =3600/K31 -> 570.47778 | ... N32: =3600/N31 -> 526.43451
B37: TIME AND MOTION STUDY SHEET
B38: Process being observed: | E38: Observer(s): | H38: DAY/TIME of observation: | K38: Name and Designation
B39: Quality Checking (Scanning - Packer assignment) - HJ | E39: Nichole Necio
B42: Step No. | C42: Elements | D42: OBSERVED TIMES (sec) | N42: Total Observed Time | P42: AVE | Q42: MAX | R42: WEIGHT PERCENTAGE | S42: Bottleneck | T42: Improvement
D43: TRIAL 1 | E43: TRIAL 2 | F43: TRIAL 3 | G43: TRIAL 4 | H43: TRIAL 5 | I43: TRIAL 6 | J43: TRIAL 7 | K43: TRIAL 8 | L43: TRIAL 9 | M43: TRIAL 10 | N43: (10trial)
B44: 1 | C44: -Scan Baskets -Insert Q.C. 2 Name -Insert Packer Name | D44: 69 | E44: 60.06 | F44: 113.09 | G44: 54 | H44: 25.29 | I44: 30.44 | J44: 78.33 | K44: 24.79 | L44: 27 | M44: 45.12 | N44: =SUM(D44:M44) -> 527.12 | P44: =AVERAGE(D44:M44) -> 52.712 | Q44: =MAX(D44:M44) -> 113.09 | R44: =P44/$P$45 -> 1 | S44: When the bin have many Q'Cs 2 makes the Q'Cs 3 stops scanning to generate the bin Q'Cs 2 and go back to scan the rest | T44: Packer must get bin that has the same Q'Cs 2 workers
C45: TOTAL Observed time (Sec) | D45: =SUM(D44) -> 69 | E45: =SUM(E44) -> 60.06 | F45: =SUM(F44) -> 113.09 | G45: =SUM(G44) -> 54 | H45: =SUM(H44) -> 25.29 | I45: =SUM(I44) -> 30.44 | J45: =SUM(J44) -> 78.33 | K45: =SUM(K44) -> 24.79 | ... M45: =SUM(M44) -> 45.12 | N45: =SUM(D45:M45) -> 527.12 | O45: TOTAL | P45: =SUM(P44) -> 52.712 | Q45: =SUM(Q44) -> 113.09 | R45: =SUM(R44) -> 1
D46: =D45/60 -> 1.15 | E46: =E45/60 -> 1.001 | F46: =F45/60 -> 1.8848333 | G46: =G45/60 -> 0.9 | J46: =J45/60 -> 1.3055 | M46: =M45/60 -> 0.752 | N46: =N45/60 -> 8.7853333
N47: minutes
C48: Order reference number | D48: 656070521786384 | E48: 652028279609242 | F48: 651965462951374 | G48: 656120989145987 | H48: 656266105410678 | I48: 6.5623615e+15 | J48: 652173010754653 | K48: 656729378360414 | L48: 652649633251405 | M48: 656569150736047
C49: Number of ORDER/Basket(s) | D49: 11 | E49: 8 | F49: 28 | G49: 11 | H49: 5 | I49: 6 | J49: 13 | K49: 7 | L49: 10 | M49: 9
C50: Packaging Type and Size (Box/Pouch) | D50: Medium | E50: Small | F50: Small | G50: Small | H50: Small | I50: Small | K50: Small | L50: Small | M50: Small
C51: Account & Brand | D51: High Jump | NIVEA | E51: High Jump | NIVEA | F51: High Jump | NIVEA | G51: High Jump | NIVEA | H51: High Jump | NIVEA | I51: High Jump | NIVEA | J51: High Jump | NIVEA | K51: High Jump | NIVEA | L51: High Jump | NIVEA | M51: High Jump | NIVEA
...

Sheet PICKING-MONDELEZ
B2: TIME AND MOTION STUDY SHEET
B3: Process being observed: | E3: Observer(s): | H3: DAY/TIME of observation: | K3: Name and Designation
B4: Picking | H4: May 16, 2023 / WED / 9:06 AM - 9:16 AM
B7: Step No. | C7: Elements | D7: OBSERVED TIMES (sec) | N7: Total Observed Time | P7: AVE | Q7: MAX | R7: WEIGHT PERCENTAGE | S7: Bottleneck | T7: Improvement
D8: TRIAL 1 | E8: TRIAL 2 | F8: TRIAL 3 | G8: TRIAL 4 | H8: TRIAL 5 | I8: TRIAL 6 | J8: TRIAL 7 | K8: TRIAL 8 | L8: TRIAL 9 | M8: TRIAL 10 | N8: (10trial)
B9: 1 | C9: Picking items on Shelves -Accepting Order -Scan Basket -Find Location -Scan Carton Q.R. -Scan Product per Quantity | D9: ='[11]PICK MONDE (HAT)'!$D$8 -> #REF! | E9: ='[11]PICK MONDE (HAT)'!$E$8 -> #REF! | F9: ='[11]PICK MONDE (HAT)'!$F$8 -> #REF! | G9: ='[11]PICK MONDE (HAT)'!$G$8 -> #REF! | H9: ='[11]PICK MONDE (HAT)'!$H$8 -> #REF! | I9: 221.67 | J9: 204.85 | K9: 461.35 | L9: 543.91 | M9: 70.48 | N9: =SUM(D9:M9) -> #REF! | P9: =AVERAGE(D9:M9) -> #REF! | Q9: =MAX(D9:M9) -> #REF! | R9: =P9/$P$11 -> #REF! | S9: Some of the Scanning Devices used doesn't automatically receive the SKU in the system, there are some steps they need to do before re-scanning again.
B10: 2 | C10: Transportation of the basket on Q.C. Station | D10: ='[11]PICK MONDE (HAT)'!$D$12 -> #REF! | E10: ='[11]PICK MONDE (HAT)'!$E$12 -> #REF! | F10: ='[11]PICK MONDE (HAT)'!$F$12 -> #REF! | G10: ='[11]PICK MONDE (HAT)'!$G$12 -> #REF! | H10: ='[11]PICK MONDE (HAT)'!$H$12 -> #REF! | I10: 6.09 | J10: 6.38 | K10: 11.96 | L10: 7.76 | M10: 9.88 | N10: =SUM(D10:M10) -> #REF! | P10: =AVERAGE(D10:M10) -> #REF! | Q10: =MAX(D10:M10) -> #REF! | R10: =P10/$P$11 -> #REF!
C11: TOTAL Observed time (Sec) | D11: =SUM(D9:D10) -> #REF! | E11: =SUM(E9:E10) -> #REF! | F11: =SUM(F9:F10) -> #REF! | G11: =SUM(G9:G10) -> #REF! | H11: =SUM(H9:H10) -> #REF! | I11: =SUM(I9:I10) -> 227.76 | J11: =SUM(J9:J10) -> 211.23 | K11: =SUM(K9:K10) -> 473.31 | ... M11: =SUM(M9:M10) -> 80.36 | N11: =SUM(D11:H11) -> #REF! | O11: TOTAL | P11: =SUM(P9:P10) -> #REF! | Q11: =SUM(Q9:Q10) -> #REF!
N12: =N11/60 -> #REF!
N13: minutes
C14: Order reference number | D14: RO-202305169555218 | E14: RO-202351617537401 | F14: RO-202352171929937 | G14: RO-20235220181797 | H14: RO2023525142633520 | I14: RO-202352882332934 | J14: RO-20235289233490 | K14: RO-202352892013501 | L14: RO-2023528812826174 | M14: RO-202352813937559
C15: Number of Item(s) | D15: 31 | E15: 7 | F15: 19 | G15: 5 | H15: 4 | I15: 6 | J15: 4 | K15: 9 | L15: 61 | M15: 1
C16: Packaging Type and Size (Box/Pouch) | D16: Medium | E16: Small | F16: Small | G16: Small | H16: Small | I16: Small | J16: Small | K16: Small | L16: Small | M16: Small
C17: Account & Brand | D17: Hatio | Mondelez | E17: Hatio | Mondelez | F17: Hatio | Mondelez | G17: Hatio | Mondelez | H17: Hatio | Mondelez | I17: Hatio | Mondelez | J17: Hatio | Mondelez | K17: Hatio | Mondelez | L17: Hatio | Mondelez | M17: Hatio | Mondelez
C18: Employee Name | D18: Edwin Tabora | E18: James Carlo Ranola | F18: Edwin Tabora | G18: RJ Anthony Villanueva | H18: RJ Anthony Villanueva | I18: RJ Anthony Villanueva | J18: RJ Anthony Villanueva | K18: RJ Anthony Villanueva | L18: Erwin Tandaan | M18: Erwin Tandaan
C19: Note/Cause of delay | D19: *Slow Device *Problem with the Device | E19: *Slow Device | G19: *Slow Device | H19: *Internet Problem | I19: * Slow Device *Bin Unreadable | J19: * Slow Device | K19: *Internet Problem *Slow Device | L19: *Having Problems Finding Locations *61 Small Items 6 Different Locations
C22: PRODUCTIVITY PER ITEM | N22: AVE
C23: PERFROMANCE RATING FACTOR % | D23: 1 | E23: 1 | F23: 1 | G23: 1 | H23: 1 | I23: 1 | J23: 1 | K23: 1 | L23: 1 | M23: 1 | N23: =AVERAGE(D23:M23) -> 1
C24: ave.OBSERVED TIME(sec) | D24: =D11/D15 -> #REF! | E24: =E11/E15 -> #REF! | F24: =F11/F15 -> #REF! | G24: =G11/G15 -> #REF! | H24: =H11/H15 -> #REF! | I24: =I11/I15 -> 37.96 | J24: =J11/J15 -> 52.8075 | K24: =K11/K15 -> 52.59 | ... M24: =M11/M15 -> 80.36 | N24: =AVERAGE(D24:M24) -> #REF!
C25: NORMAL TIME = observed * PRF (sec) | D25: =D24*D23 -> #REF! | E25: =E24*E23 -> #REF! | F25: =F24*F23 -> #REF! | G25: =G24*G23 -> #REF! | H25: =H24*H23 -> #REF! | I25: =I24*I23 -> 37.96 | J25: =J24*J23 -> 52.8075 | K25: =K24*K23 -> 52.59 | ... M25: =M24*M23 -> 80.36 | N25: =AVERAGE(D25:M25) -> #REF!
C26: STANDARD TIME =Normal Time *[1+ Allowance Factor(5%)] | D26: =D25*(1+0.05) -> #REF! | E26: =E25*(1+0.05) -> #REF! | F26: =F25*(1+0.05) -> #REF! | G26: =G25*(1+0.05) -> #REF! | H26: =H25*(1+0.05) -> #REF! | I26: =I25*(1+0.05) -> 39.858 | J26: =J25*(1+0.05) -> 55.447875 | K26: =K25*(1+0.05) -> 55.2195 | ... M26: =M25*(1+0.05) -> 84.378 | N26: =AVERAGE(D26:M26) -> #REF!
C27: STANDARD PRODUCTIVITY PER MAN-HOUR | D27: =(D26/3600)*100 -> #REF! | E27: =(E26/3600)*100 -> #REF! | F27: =(F26/3600)*100 -> #REF! | G27: =(G26/3600)*100 -> #REF! | H27: =(H26/3600)*100 -> #REF! | I27: =(I26/3600)*100 -> 1.1071667 | J27: =(J26/3600)*100 -> 1.5402187 | K27: =(K26/3600)*100 -> 1.533875 | ... M27: =(M26/3600)*100 -> 2.3438333 | N27: =3600/N26 -> #REF!
C29: allowance | D29: 0.05
C30: manhour | D30: 1hr = 3600sec

Sheet PICKING-PILMICO
B2: TIME AND MOTION STUDY SHEET
B3: Process being observed: | E3: Observer(s): | H3: DAY/TIME of observation: | K3: Name and Designation
B4: Picking | E4: Hans David Wenceslao | H4: May 26, 2023 / 10 AM onwards |
